[2025-04-10T18:20:59.539+0000] {local_task_job_runner.py:120} INFO - ::group::Pre task execution logs
[2025-04-10T18:20:59.582+0000] {taskinstance.py:2073} INFO - Dependencies all met for dep_context=non-requeueable deps ti=<TaskInstance: data_processing_pipeline.raw_to_bronze manual__2025-04-10T18:20:50.148048+00:00 [queued]>
[2025-04-10T18:20:59.595+0000] {taskinstance.py:2073} INFO - Dependencies all met for dep_context=requeueable deps ti=<TaskInstance: data_processing_pipeline.raw_to_bronze manual__2025-04-10T18:20:50.148048+00:00 [queued]>
[2025-04-10T18:20:59.596+0000] {taskinstance.py:2303} INFO - Starting attempt 1 of 2
[2025-04-10T18:20:59.618+0000] {taskinstance.py:2327} INFO - Executing <Task(PythonOperator): raw_to_bronze> on 2025-04-10 18:20:50.148048+00:00
[2025-04-10T18:20:59.633+0000] {warnings.py:110} WARNING - /home/***/.local/lib/python3.12/site-packages/***/task/task_runner/standard_task_runner.py:61: DeprecationWarning: This process (pid=3349) is multi-threaded, use of fork() may lead to deadlocks in the child.
  pid = os.fork()

[2025-04-10T18:20:59.635+0000] {standard_task_runner.py:90} INFO - Running: ['***', 'tasks', 'run', 'data_processing_pipeline', 'raw_to_bronze', 'manual__2025-04-10T18:20:50.148048+00:00', '--job-id', '5', '--raw', '--subdir', 'DAGS_FOLDER/data_processing_dag.py', '--cfg-path', '/tmp/tmpwg01b5ps']
[2025-04-10T18:20:59.638+0000] {standard_task_runner.py:63} INFO - Started process 3351 to run task
[2025-04-10T18:20:59.638+0000] {standard_task_runner.py:91} INFO - Job 5: Subtask raw_to_bronze
[2025-04-10T18:20:59.799+0000] {task_command.py:426} INFO - Running <TaskInstance: data_processing_pipeline.raw_to_bronze manual__2025-04-10T18:20:50.148048+00:00 [running]> on host 8ff57cdf7c3f
[2025-04-10T18:21:00.002+0000] {taskinstance.py:2644} INFO - Exporting env vars: AIRFLOW_CTX_DAG_OWNER='***' AIRFLOW_CTX_DAG_ID='data_processing_pipeline' AIRFLOW_CTX_TASK_ID='raw_to_bronze' AIRFLOW_CTX_EXECUTION_DATE='2025-04-10T18:20:50.148048+00:00' AIRFLOW_CTX_TRY_NUMBER='1' AIRFLOW_CTX_DAG_RUN_ID='manual__2025-04-10T18:20:50.148048+00:00'
[2025-04-10T18:21:00.006+0000] {taskinstance.py:430} INFO - ::endgroup::
[2025-04-10T18:21:00.007+0000] {logging_mixin.py:188} INFO - Iniciando carregamento de dados brutos para Bronze...
[2025-04-10T18:21:00.014+0000] {logging_mixin.py:188} INFO - Erro ao carregar dados para Bronze: [Errno 2] No such file or directory: '/opt/***/data/0_raw/raw_data.csv'
[2025-04-10T18:21:00.015+0000] {taskinstance.py:441} INFO - ::group::Post task execution logs
[2025-04-10T18:21:00.016+0000] {taskinstance.py:2890} ERROR - Task failed with exception
Traceback (most recent call last):
  File "/home/airflow/.local/lib/python3.12/site-packages/airflow/models/taskinstance.py", line 465, in _execute_task
    result = _execute_callable(context=context, **execute_callable_kwargs)
             ^^^^^^^^^^^^^^^^^^^^^^^^^^^^^^^^^^^^^^^^^^^^^^^^^^^^^^^^^^^^^
  File "/home/airflow/.local/lib/python3.12/site-packages/airflow/models/taskinstance.py", line 432, in _execute_callable
    return execute_callable(context=context, **execute_callable_kwargs)
           ^^^^^^^^^^^^^^^^^^^^^^^^^^^^^^^^^^^^^^^^^^^^^^^^^^^^^^^^^^^^
  File "/home/airflow/.local/lib/python3.12/site-packages/airflow/models/baseoperator.py", line 400, in wrapper
    return func(self, *args, **kwargs)
           ^^^^^^^^^^^^^^^^^^^^^^^^^^^
  File "/home/airflow/.local/lib/python3.12/site-packages/airflow/operators/python.py", line 235, in execute
    return_value = self.execute_callable()
                   ^^^^^^^^^^^^^^^^^^^^^^^
  File "/home/airflow/.local/lib/python3.12/site-packages/airflow/operators/python.py", line 252, in execute_callable
    return self.python_callable(*self.op_args, **self.op_kwargs)
           ^^^^^^^^^^^^^^^^^^^^^^^^^^^^^^^^^^^^^^^^^^^^^^^^^^^^^
  File "/opt/airflow/dags/data_processing_dag.py", line 33, in upload_raw_data_to_bronze
    raise e
  File "/opt/airflow/dags/data_processing_dag.py", line 26, in upload_raw_data_to_bronze
    df = pd.read_csv(RAW_DATA_PATH)
         ^^^^^^^^^^^^^^^^^^^^^^^^^^
  File "/home/airflow/.local/lib/python3.12/site-packages/pandas/io/parsers/readers.py", line 948, in read_csv
    return _read(filepath_or_buffer, kwds)
           ^^^^^^^^^^^^^^^^^^^^^^^^^^^^^^^
  File "/home/airflow/.local/lib/python3.12/site-packages/pandas/io/parsers/readers.py", line 611, in _read
    parser = TextFileReader(filepath_or_buffer, **kwds)
             ^^^^^^^^^^^^^^^^^^^^^^^^^^^^^^^^^^^^^^^^^^
  File "/home/airflow/.local/lib/python3.12/site-packages/pandas/io/parsers/readers.py", line 1448, in __init__
    self._engine = self._make_engine(f, self.engine)
                   ^^^^^^^^^^^^^^^^^^^^^^^^^^^^^^^^^
  File "/home/airflow/.local/lib/python3.12/site-packages/pandas/io/parsers/readers.py", line 1705, in _make_engine
    self.handles = get_handle(
                   ^^^^^^^^^^^
  File "/home/airflow/.local/lib/python3.12/site-packages/pandas/io/common.py", line 863, in get_handle
    handle = open(
             ^^^^^
FileNotFoundError: [Errno 2] No such file or directory: '/opt/airflow/data/0_raw/raw_data.csv'
[2025-04-10T18:21:00.053+0000] {taskinstance.py:1205} INFO - Marking task as UP_FOR_RETRY. dag_id=data_processing_pipeline, task_id=raw_to_bronze, execution_date=20250410T182050, start_date=20250410T182059, end_date=20250410T182100
[2025-04-10T18:21:00.076+0000] {standard_task_runner.py:110} ERROR - Failed to execute job 5 for task raw_to_bronze ([Errno 2] No such file or directory: '/opt/airflow/data/0_raw/raw_data.csv'; 3351)
[2025-04-10T18:21:00.135+0000] {local_task_job_runner.py:240} INFO - Task exited with return code 1
[2025-04-10T18:21:00.175+0000] {taskinstance.py:3482} INFO - 0 downstream tasks scheduled from follow-on schedule check
[2025-04-10T18:21:00.178+0000] {local_task_job_runner.py:222} INFO - ::endgroup::
