[2025-04-10T20:04:41.215+0000] {local_task_job_runner.py:120} INFO - ::group::Pre task execution logs
[2025-04-10T20:04:41.274+0000] {taskinstance.py:2073} INFO - Dependencies all met for dep_context=non-requeueable deps ti=<TaskInstance: data_processing_pipeline.raw_to_bronze manual__2025-04-10T19:59:36.426171+00:00 [queued]>
[2025-04-10T20:04:41.289+0000] {taskinstance.py:2073} INFO - Dependencies all met for dep_context=requeueable deps ti=<TaskInstance: data_processing_pipeline.raw_to_bronze manual__2025-04-10T19:59:36.426171+00:00 [queued]>
[2025-04-10T20:04:41.290+0000] {taskinstance.py:2303} INFO - Starting attempt 2 of 2
[2025-04-10T20:04:41.579+0000] {taskinstance.py:2327} INFO - Executing <Task(PythonOperator): raw_to_bronze> on 2025-04-10 19:59:36.426171+00:00
[2025-04-10T20:04:41.596+0000] {standard_task_runner.py:90} INFO - Running: ['***', 'tasks', 'run', 'data_processing_pipeline', 'raw_to_bronze', 'manual__2025-04-10T19:59:36.426171+00:00', '--job-id', '12', '--raw', '--subdir', 'DAGS_FOLDER/data_processing_dag.py', '--cfg-path', '/tmp/tmpxtj8qpxx']
[2025-04-10T20:04:41.602+0000] {standard_task_runner.py:91} INFO - Job 12: Subtask raw_to_bronze
[2025-04-10T20:04:41.604+0000] {logging_mixin.py:188} WARNING - /home/***/.local/lib/python3.12/site-packages/***/task/task_runner/standard_task_runner.py:61 DeprecationWarning: This process (pid=806) is multi-threaded, use of fork() may lead to deadlocks in the child.
[2025-04-10T20:04:41.606+0000] {standard_task_runner.py:63} INFO - Started process 808 to run task
[2025-04-10T20:04:41.692+0000] {task_command.py:426} INFO - Running <TaskInstance: data_processing_pipeline.raw_to_bronze manual__2025-04-10T19:59:36.426171+00:00 [running]> on host 2437c75233d1
[2025-04-10T20:04:41.841+0000] {taskinstance.py:2644} INFO - Exporting env vars: AIRFLOW_CTX_DAG_OWNER='***' AIRFLOW_CTX_DAG_ID='data_processing_pipeline' AIRFLOW_CTX_TASK_ID='raw_to_bronze' AIRFLOW_CTX_EXECUTION_DATE='2025-04-10T19:59:36.426171+00:00' AIRFLOW_CTX_TRY_NUMBER='2' AIRFLOW_CTX_DAG_RUN_ID='manual__2025-04-10T19:59:36.426171+00:00'
[2025-04-10T20:04:41.844+0000] {taskinstance.py:430} INFO - ::endgroup::
[2025-04-10T20:04:41.871+0000] {logging_mixin.py:188} INFO - Iniciando carregamento de dados brutos para Bronze...
[2025-04-10T20:04:41.872+0000] {logging_mixin.py:188} INFO - RAW_DATA_PATH: /opt/***/data/0_raw/raw_data.csv
[2025-04-10T20:04:41.878+0000] {logging_mixin.py:188} INFO - Erro ao carregar dados para Bronze: [Errno 2] No such file or directory: '/opt/***/data/0_raw/raw_data.csv'
[2025-04-10T20:04:41.878+0000] {taskinstance.py:441} INFO - ::group::Post task execution logs
[2025-04-10T20:04:41.879+0000] {taskinstance.py:2890} ERROR - Task failed with exception
Traceback (most recent call last):
  File "/home/airflow/.local/lib/python3.12/site-packages/airflow/models/taskinstance.py", line 465, in _execute_task
    result = _execute_callable(context=context, **execute_callable_kwargs)
             ^^^^^^^^^^^^^^^^^^^^^^^^^^^^^^^^^^^^^^^^^^^^^^^^^^^^^^^^^^^^^
  File "/home/airflow/.local/lib/python3.12/site-packages/airflow/models/taskinstance.py", line 432, in _execute_callable
    return execute_callable(context=context, **execute_callable_kwargs)
           ^^^^^^^^^^^^^^^^^^^^^^^^^^^^^^^^^^^^^^^^^^^^^^^^^^^^^^^^^^^^
  File "/home/airflow/.local/lib/python3.12/site-packages/airflow/models/baseoperator.py", line 400, in wrapper
    return func(self, *args, **kwargs)
           ^^^^^^^^^^^^^^^^^^^^^^^^^^^
  File "/home/airflow/.local/lib/python3.12/site-packages/airflow/operators/python.py", line 235, in execute
    return_value = self.execute_callable()
                   ^^^^^^^^^^^^^^^^^^^^^^^
  File "/home/airflow/.local/lib/python3.12/site-packages/airflow/operators/python.py", line 252, in execute_callable
    return self.python_callable(*self.op_args, **self.op_kwargs)
           ^^^^^^^^^^^^^^^^^^^^^^^^^^^^^^^^^^^^^^^^^^^^^^^^^^^^^
  File "/opt/airflow/dags/app/data_processing.py", line 130, in upload_raw_data_to_bronze
    raise e
  File "/opt/airflow/dags/app/data_processing.py", line 121, in upload_raw_data_to_bronze
    df = pd.read_csv(paths.RAW_DATA_PATH)
         ^^^^^^^^^^^^^^^^^^^^^^^^^^^^^^^^
  File "/home/airflow/.local/lib/python3.12/site-packages/pandas/io/parsers/readers.py", line 948, in read_csv
    return _read(filepath_or_buffer, kwds)
           ^^^^^^^^^^^^^^^^^^^^^^^^^^^^^^^
  File "/home/airflow/.local/lib/python3.12/site-packages/pandas/io/parsers/readers.py", line 611, in _read
    parser = TextFileReader(filepath_or_buffer, **kwds)
             ^^^^^^^^^^^^^^^^^^^^^^^^^^^^^^^^^^^^^^^^^^
  File "/home/airflow/.local/lib/python3.12/site-packages/pandas/io/parsers/readers.py", line 1448, in __init__
    self._engine = self._make_engine(f, self.engine)
                   ^^^^^^^^^^^^^^^^^^^^^^^^^^^^^^^^^
  File "/home/airflow/.local/lib/python3.12/site-packages/pandas/io/parsers/readers.py", line 1705, in _make_engine
    self.handles = get_handle(
                   ^^^^^^^^^^^
  File "/home/airflow/.local/lib/python3.12/site-packages/pandas/io/common.py", line 863, in get_handle
    handle = open(
             ^^^^^
FileNotFoundError: [Errno 2] No such file or directory: '/opt/airflow/data/0_raw/raw_data.csv'
[2025-04-10T20:04:41.903+0000] {taskinstance.py:1205} INFO - Marking task as FAILED. dag_id=data_processing_pipeline, task_id=raw_to_bronze, execution_date=20250410T195936, start_date=20250410T200441, end_date=20250410T200441
[2025-04-10T20:04:41.923+0000] {standard_task_runner.py:110} ERROR - Failed to execute job 12 for task raw_to_bronze ([Errno 2] No such file or directory: '/opt/airflow/data/0_raw/raw_data.csv'; 808)
[2025-04-10T20:04:41.943+0000] {local_task_job_runner.py:240} INFO - Task exited with return code 1
[2025-04-10T20:04:41.979+0000] {taskinstance.py:3482} INFO - 0 downstream tasks scheduled from follow-on schedule check
[2025-04-10T20:04:41.987+0000] {local_task_job_runner.py:222} INFO - ::endgroup::
